#VRML_SIM R2021a utf8
WorldInfo {
}
Viewpoint {
  orientation 0.3315418914934481 0.5580990967040169 0.7606611416676333 2.328317741458344
  position 0.6075079608010802 0.4996890210177798 0.2591156636369786
}
TexturedBackground {
}
TexturedBackgroundLight {
}
Robot {
  rotation 0 0 1 0
  children [
    Transform {
      translation 0 -0.0825 0
      children [
        HingeJoint {
          jointParameters HingeJointParameters {
            axis 0 1 0
          }
          device [
            RotationalMotor {
              name "right wheel motor"
              maxVelocity 50
            }
            PositionSensor {
              name "right wheel sensor"
            }
          ]
          endPoint Solid {
            children [
              DEF WHEEL Shape {
                appearance DEF dark PBRAppearance {
                  baseColor 0.1 0.1 0.1
                  roughness 1
                  metalness 0.5
                }
                geometry Cylinder {
                  height 0.01
                  radius 0.025
                }
              }
            ]
            name "wheel_right_link(1)"
            boundingObject USE WHEEL
            physics DEF WHEEL_PHYSICS Physics {
            }
          }
        }
      ]
    }
    Transform {
      translation 0 0.0825 0
      children [
        HingeJoint {
          jointParameters HingeJointParameters {
            axis 0 1 0
          }
          device [
            RotationalMotor {
              name "left wheel motor"
              maxVelocity 50
            }
            PositionSensor {
              name "left wheel sensor"
            }
          ]
          endPoint Solid {
            children [
              USE WHEEL
            ]
            name "wheel_left_link"
            boundingObject USE WHEEL
            physics USE WHEEL_PHYSICS
          }
        }
      ]
    }
    Solid {
      translation -0.06 0 -0.005
      name "solid(1)"
      contactMaterial "free_wheel"
      boundingObject DEF FREE_WHEEL Sphere {
        radius 0.02
        subdivision 2
      }
      physics Physics {
      }
    }
    Solid {
      translation 0.05 0 -0.005
      contactMaterial "free_wheel"
      boundingObject USE FREE_WHEEL
      physics Physics {
      }
    }
    DEF BOTTOM_SHAPE Transform {
      translation -0.089 -0.16 0
      rotation 0 1 0 1.5708
      children [
        Shape {
          appearance PBRAppearance {
            baseColor 0.552148 0.547127 0.555932
            metalness 0.5
          }
          geometry Mesh {
            url [
              "/Users/pymzor/Projets/jeroboam/cdr/protos/Robot/mesh/plaque_coupee.stl"
            ]
          }
        }
      ]
    }
  ]
  name "robot_1"
  boundingObject USE BOTTOM_SHAPE
  physics Physics {
    density -1
    mass 6
    centerOfMass [
      0 0 -0.1
    ]
  }
  controller "none"
  supervisor TRUE
  synchronization FALSE
}
